---
metatable: false
title: Исключение, выброшенное в конструкторе или деструкторе
tags:
dateCreated: 25-го августа 2022
dateModified: 25-го августа 2022
---
# Исключение, выброшенное в конструкторе или деструкторе

### Исключение в конструкторе

В случае возникновения исключения в конструкторе произойдут следующие вещи:
- Объект не будет создан, как следствие не будет вызван его деструктор.
- Стандарт C++ гарантирует то, что у полей класса, которые были сконструированы до возникновения исключения, будут вызваны деструкторы.
- Есть риск возникновения утечки памяти при использовании "сырых указателей".

Пример:

```cpp
#include <iostream>

struct B {  
public:  
    explicit B() {  
        std::cout << "B ctor" << std::endl;  
    }  
  
    B(const B&) {  
        std::cout << "B copy" << std::endl;  
    }  
  
    ~B() {  
        std::cout << "B dtor" << std::endl;  
    }  
};  
  
struct A {  
public:  
    explicit A(const B& b) : b(b) {   
        throw std::runtime_error("A exception");  
		std::cout << "A ctor" << std::endl; 
    }  
  
    ~A() {  
        std::cout << "A dtor" << std::endl;  
    }  
  
    B b;  
};  
  
int main() {  
    try {  
        auto b  = B();  
        auto* a = new A(b);  
        delete a;  
    }  
    catch (const std::exception& ex) {  
        std::cout << ex.what() << std::endl;  
    }  
   
    return EXIT_SUCCESS;  
}
```

Вывод программы:

```
B ctor
B copy
B dtor
B dtor
A exception
```

Вывод показывает, что количество успешно завершенных конструкторов равно количеству вызванных деструкторов. Это гарантия того, что объекты в стеке будут исправно освобождены.

Если поменять код класса `A` на вот этот:

```cpp
struct A {
public:
    explicit A(const B& b) : b(new B(b)) {
        throw std::runtime_error("A exception");
        std::cout << "A ctor" << std::endl;
    }

    ~A() {
        delete this->b;
        std::cout << "A dtor" << std::endl;
    }

    B* b;
};
```

Вывод будет изменён:

```
B ctor
B copy
B dtor
A exception
```

Что означает, что не был вызван деструктор у одного экземпляра класса `B`. Это предсказуемо, так как он вызывается в деструкторе класса `A`, который в свою очередь не был вызван.

Первый пример показывает преимущества идиомы RAII (подробнее [тут](RAII.md)).

### Исключение в деструкторе

Если исключение в конструкторе является более или менее нормальной практикой, то исключение в деструкторе наоборот, очень опасная вещь, которая приводит к **неопределённому поведению (UB)**.

Это связано с тем, что объект находится в "подвешенном состоянии", являясь не до конца уничтоженным, что в свою очередь приводит к утечкам памяти и прочим неприятностям.

Пример:

```cpp
#include <iostream>

struct B {  
public:  
    explicit B() {  
        std::cout << "B ctor" << std::endl;  
    }  
  
    B(const B&) {  
        std::cout << "B copy" << std::endl;  
    }  
  
    ~B() {  
        std::cout << "B dtor" << std::endl;  
    }  
}; 

struct A {
public:
    explicit A(const B& b) : b(b) {
        std::cout << "A ctor" << std::endl;
    }

    ~A() {
        throw std::runtime_error("A exception");
        std::cout << "A dtor" << std::endl;
    }

    B b;
};

  
int main() {  
    try {  
        auto b  = B();  
        auto* a = new A(b);  
        delete a;  
    }  
    catch (const std::exception& ex) {  
        std::cout << ex.what() << std::endl;  
    }  
   
    return EXIT_SUCCESS;  
}
```

Предполагаемый вывод программы:

```cpp
B ctor
B copy
A ctor
```
